<?xml version="1.0" encoding="utf-8" ?>
<!-- This URDF was automatically created by SolidWorks to URDF Exporter! Originally created by Stephen Brawner (brawner@gmail.com)
     Commit Version: 1.6.0-1-g15f4949  Build Version: 1.6.7594.29634
     For more information, please see http://wiki.ros.org/sw_urdf_exporter -->
<robot name="capstone_arm">
    <link name="link0">

        <inertial>
            <origin xyz="0.28587 -0.24055 0.082819" rpy="0 0 0" />
            <mass value="1" />
            <inertia ixx="1" ixy="0" ixz="0" iyy="1" iyz="0" izz="1" />
        </inertial>

        <visual>
            <origin xyz="0 0 0" rpy="0 0 0" />
            <geometry>
                <mesh filename="package://capstone_arm/meshes/link0.STL" />
            </geometry>
            <material name="">
                <color rgba="0.8 0.8 0.8 1" />
            </material>
        </visual>
        <collision>
            <origin xyz="0 0 0" rpy="0 0 0" />
            <geometry>
                <mesh filename="package://capstone_arm/meshes/link0.STL" />
            </geometry>
        </collision>
    </link>
    <link name="link1">

        <inertial>
            <origin xyz="-0.059664 0.056998 0.023891" rpy="0 0 0" />
            <mass value="0.6678" />
            <inertia ixx="0.00068503" ixy="8.5049E-05" ixz="0.00015076" iyy="0.00089" iyz="-2.8362E-05" izz="0.00065643" />
        </inertial>

        <visual>
            <origin xyz="0 0 0" rpy="0 0 0" />
            <geometry>
                <mesh filename="package://capstone_arm/meshes/link1.STL" />
            </geometry>
            <material name="">
                <color rgba="0.25098 0.25098 0.25098 1" />
            </material>
        </visual>
        <collision>
            <origin xyz="0 0 0" rpy="0 0 0" />
            <geometry>
                <mesh filename="package://capstone_arm/meshes/link1.STL" />
            </geometry>
        </collision>
    </link>
    <joint name="joint1" type="revolute">
        <origin xyz="0 -0.01165 0.51" rpy="3.1416 0 0" />
        <parent link="link0" />
        <child link="link1" />
        <axis xyz="0 1 0" />
        <limit lower="-2.6" upper="2.6" effort="50" velocity="10" />
    </joint>
    <link name="link2">

        <inertial>
            <origin xyz="0.0071665 0.0062904 -0.012775" rpy="0 0 0" />
            <mass value="0.40468" />
            <inertia ixx="0.00016357" ixy="-2.969E-06" ixz="-1.3946E-06" iyy="0.00022393" iyz="4.4635E-06" izz="0.00011225" />
        </inertial>

        <visual>
            <origin xyz="0 0 0" rpy="0 0 0" />
            <geometry>
                <mesh filename="package://capstone_arm/meshes/link2.STL" />
            </geometry>
            <material name="">
                <color rgba="0.25098 0.25098 0.25098 1" />
            </material>
        </visual>
        <collision>
            <origin xyz="0 0 0" rpy="0 0 0" />
            <geometry>
                <mesh filename="package://capstone_arm/meshes/link2.STL" />
            </geometry>
        </collision>
    </link>
    <joint name="joint2" type="revolute">
        <origin xyz="0 0.068 0" rpy="0 0 0" />
        <parent link="link1" />
        <child link="link2" />
        <axis xyz="1 0 0" />
        <limit lower="-0.7" upper="1.57" effort="50" velocity="10" />
    </joint>
    <link name="link3">

        <inertial>
            <origin xyz="-0.25153 0.0048935 -0.019697" rpy="0 0 0" />
            <mass value="0.69216" />
            <inertia ixx="0.00044645" ixy="1.3124E-05" ixz="-8.4613E-06" iyy="0.0019095" iyz="3.2032E-06" izz="0.0019424" />
        </inertial>

        <visual>
            <origin xyz="0 0 0" rpy="0 0 0" />
            <geometry>
                <mesh filename="package://capstone_arm/meshes/link3.STL" />
            </geometry>
            <material name="">
                <color rgba="0.8 0.8 0.8 1" />
            </material>
        </visual>
        <collision>
            <origin xyz="0 0 0" rpy="0 0 0" />
            <geometry>
                <mesh filename="package://capstone_arm/meshes/link3.STL" />
            </geometry>
        </collision>
    </link>
    <joint name="joint3" type="revolute">
        <origin xyz="0 0.035472 0" rpy="-1.5708 0 -1.5708" />
        <parent link="link2" />
        <child link="link3" />
        <axis xyz="1 0 0" />
        <limit lower="-2.35" upper="2.35" effort="50" velocity="10" />
    </joint>
    <link name="link4">

        <inertial>
            <origin xyz="0.010928 0.0044617 0.0113" rpy="0 0 0" />
            <mass value="0.1845" />
            <inertia ixx="4.2498E-05" ixy="-3.4654E-07" ixz="4.6627E-07" iyy="3.9796E-05" iyz="-2.4994E-06" izz="3.1939E-05" />
        </inertial>

        <visual>
            <origin xyz="0 0 0" rpy="0 0 0" />
            <geometry>
                <mesh filename="package://capstone_arm/meshes/link4.STL" />
            </geometry>
            <material name="">
                <color rgba="0.25098 0.25098 0.25098 1" />
            </material>
        </visual>
        <collision>
            <origin xyz="0 0 0" rpy="0 0 0" />
            <geometry>
                <mesh filename="package://capstone_arm/meshes/link4.STL" />
            </geometry>
        </collision>
    </link>
    <joint name="joint4" type="revolute">
        <origin xyz="-0.359 0.02955 0" rpy="1.5708 -1.5708 0" />
        <parent link="link3" />
        <child link="link4" />
        <axis xyz="1 0 0" />
        <limit lower="-2.79" upper="0.175" effort="50" velocity="10" />
    </joint>
    <link name="link5">

        <inertial>
            <origin xyz="-0.21779 0.008534 0.0021872" rpy="0 0 0" />
            <mass value="0.43746" />
            <inertia ixx="0.00021274" ixy="4.618E-06" ixz="2.6716E-06" iyy="0.0017532" iyz="-2.3971E-06" izz="0.0017555" />
        </inertial>

        <visual>
            <origin xyz="0 0 0" rpy="0 0 0" />
            <geometry>
                <mesh filename="package://capstone_arm/meshes/link5.STL" />
            </geometry>
            <material name="">
                <color rgba="0.8 0.8 0.8 1" />
            </material>
        </visual>
        <collision>
            <origin xyz="0 0 0" rpy="0 0 0" />
            <geometry>
                <mesh filename="package://capstone_arm/meshes/link5.STL" />
            </geometry>
        </collision>
    </link>
    <joint name="joint5" type="revolute">
        <origin xyz="0 0.0306 0.02955" rpy="-1.5708 0 -1.5708" />
        <parent link="link4" />
        <child link="link5" />
        <axis xyz="1 0 0" />
        <limit lower="-3.92" upper="0.785" effort="50" velocity="10" />
    </joint>
    <link name="link6">

        <inertial>
            <origin xyz="0.0046648 -0.099034 -0.0026804" rpy="0 0 0" />
            <mass value="0.91456" />
            <inertia ixx="0.0015854" ixy="8.003E-08" ixz="-3.5648E-08" iyy="0.00086703" iyz="-0.00013542" izz="0.0017628" />
        </inertial>

        <visual>
            <origin xyz="0 0 0" rpy="0 0 0" />
            <geometry>
                <mesh filename="package://capstone_arm/meshes/link6.STL" />
            </geometry>
            <material name="">
                <color rgba="0.25098 0.25098 0.25098 1" />
            </material>
        </visual>
        <collision>
            <origin xyz="0 0 0" rpy="0 0 0" />
            <geometry>
                <mesh filename="package://capstone_arm/meshes/link6.STL" />
            </geometry>
        </collision>
    </link>
    <joint name="joint6" type="revolute">
        <origin xyz="-0.3511 0 0" rpy="0 0 -1.5708" />
        <parent link="link5" />
        <child link="link6" />
        <axis xyz="1 0 0" />
        <limit lower="-1.30" upper="1.30" effort="50" velocity="10" />
    </joint>

    <transmission name="trans_joint1">
        <type>transmission_interface/SimpleTransmission</type>
        <joint name="joint1">
            <hardwareInterface>hardware_interface/PositionJointInterface</hardwareInterface>
        </joint>
        <actuator name="joint1_motor">
            <hardwareInterface>hardware_interface/PositionJointInterface</hardwareInterface>
            <mechanicalReduction>1</mechanicalReduction>
        </actuator>
    </transmission>
    <transmission name="trans_joint2">
        <type>transmission_interface/SimpleTransmission</type>
        <joint name="joint2">
            <hardwareInterface>hardware_interface/PositionJointInterface</hardwareInterface>
        </joint>
        <actuator name="joint2_motor">
            <hardwareInterface>hardware_interface/PositionJointInterface</hardwareInterface>
            <mechanicalReduction>1</mechanicalReduction>
        </actuator>
    </transmission>
    <transmission name="trans_joint3">
        <type>transmission_interface/SimpleTransmission</type>
        <joint name="joint3">
            <hardwareInterface>hardware_interface/PositionJointInterface</hardwareInterface>
        </joint>
        <actuator name="joint3_motor">
            <hardwareInterface>hardware_interface/PositionJointInterface</hardwareInterface>
            <mechanicalReduction>1</mechanicalReduction>
        </actuator>
    </transmission>
    <transmission name="trans_joint4">
        <type>transmission_interface/SimpleTransmission</type>
        <joint name="joint4">
            <hardwareInterface>hardware_interface/PositionJointInterface</hardwareInterface>
        </joint>
        <actuator name="joint4_motor">
            <hardwareInterface>hardware_interface/PositionJointInterface</hardwareInterface>
            <mechanicalReduction>1</mechanicalReduction>
        </actuator>
    </transmission>
    <transmission name="trans_joint5">
        <type>transmission_interface/SimpleTransmission</type>
        <joint name="joint5">
            <hardwareInterface>hardware_interface/PositionJointInterface</hardwareInterface>
        </joint>
        <actuator name="joint5_motor">
            <hardwareInterface>hardware_interface/PositionJointInterface</hardwareInterface>
            <mechanicalReduction>1</mechanicalReduction>
        </actuator>
    </transmission>
    <transmission name="trans_joint6">
        <type>transmission_interface/SimpleTransmission</type>
        <joint name="joint6">
            <hardwareInterface>hardware_interface/PositionJointInterface</hardwareInterface>
        </joint>
        <actuator name="joint6_motor">
            <hardwareInterface>hardware_interface/PositionJointInterface</hardwareInterface>
            <mechanicalReduction>1</mechanicalReduction>
        </actuator>
    </transmission>
    <gazebo>
        <plugin name="gazebo_ros_control" filename="libgazebo_ros_control.so">
            <robotNamespace>/</robotNamespace>
        </plugin>
    </gazebo>
</robot>
